[2024-03-13T00:29:35.578-0400] {taskinstance.py:1979} INFO - Dependencies all met for dep_context=non-requeueable deps ti=<TaskInstance: predict_data.validate_test scheduled__2024-03-12T00:00:00+00:00 [queued]>
[2024-03-13T00:29:35.587-0400] {taskinstance.py:1979} INFO - Dependencies all met for dep_context=requeueable deps ti=<TaskInstance: predict_data.validate_test scheduled__2024-03-12T00:00:00+00:00 [queued]>
[2024-03-13T00:29:35.588-0400] {taskinstance.py:2193} INFO - Starting attempt 1 of 3
[2024-03-13T00:29:35.621-0400] {taskinstance.py:2217} INFO - Executing <Task(PythonOperator): validate_test> on 2024-03-12 00:00:00+00:00
[2024-03-13T00:29:35.634-0400] {standard_task_runner.py:60} INFO - Started process 432715 to run task
[2024-03-13T00:29:35.641-0400] {standard_task_runner.py:87} INFO - Running: ['airflow', 'tasks', 'run', 'predict_data', 'validate_test', 'scheduled__2024-03-12T00:00:00+00:00', '--job-id', '112', '--raw', '--subdir', 'DAGS_FOLDER/test_dag.py', '--cfg-path', '/tmp/tmp8ig4scof']
[2024-03-13T00:29:35.642-0400] {standard_task_runner.py:88} INFO - Job 112: Subtask validate_test
[2024-03-13T00:29:35.714-0400] {task_command.py:423} INFO - Running <TaskInstance: predict_data.validate_test scheduled__2024-03-12T00:00:00+00:00 [running]> on host DESKTOP-6U7QAQN.
[2024-03-13T00:29:35.825-0400] {taskinstance.py:2513} INFO - Exporting env vars: AIRFLOW_CTX_DAG_EMAIL='youremail@email.com' AIRFLOW_CTX_DAG_OWNER='airflow' AIRFLOW_CTX_DAG_ID='predict_data' AIRFLOW_CTX_TASK_ID='validate_test' AIRFLOW_CTX_EXECUTION_DATE='2024-03-12T00:00:00+00:00' AIRFLOW_CTX_TRY_NUMBER='1' AIRFLOW_CTX_DAG_RUN_ID='scheduled__2024-03-12T00:00:00+00:00'
[2024-03-13T00:29:35.832-0400] {taskinstance.py:2731} ERROR - Task failed with exception
Traceback (most recent call last):
  File "/home/ironbong_jr/mlops/project/project/lib/python3.10/site-packages/airflow/models/taskinstance.py", line 444, in _execute_task
    result = _execute_callable(context=context, **execute_callable_kwargs)
  File "/home/ironbong_jr/mlops/project/project/lib/python3.10/site-packages/airflow/models/taskinstance.py", line 414, in _execute_callable
    return execute_callable(context=context, **execute_callable_kwargs)
  File "/home/ironbong_jr/mlops/project/project/lib/python3.10/site-packages/airflow/operators/python.py", line 200, in execute
    return_value = self.execute_callable()
  File "/home/ironbong_jr/mlops/project/project/lib/python3.10/site-packages/airflow/operators/python.py", line 217, in execute_callable
    return self.python_callable(*self.op_args, **self.op_kwargs)
  File "/home/ironbong_jr/mlops/project/Group-5-Default-of-Credit-Card-Clients-IE7374/airflow/dags/validate_data/new_data_validate.py", line 11, in new_data_val
    schema = tfdv.load_schema_text(schemaPath)
  File "/home/ironbong_jr/mlops/project/project/lib/python3.10/site-packages/tensorflow_data_validation/utils/schema_util.py", line 210, in load_schema_text
    schema_text = io_util.read_file_to_string(input_path)
  File "/home/ironbong_jr/mlops/project/project/lib/python3.10/site-packages/tensorflow_data_validation/utils/io_util.py", line 52, in read_file_to_string
    return f.read()
  File "/home/ironbong_jr/mlops/project/project/lib/python3.10/site-packages/tensorflow/python/lib/io/file_io.py", line 116, in read
    self._preread_check()
  File "/home/ironbong_jr/mlops/project/project/lib/python3.10/site-packages/tensorflow/python/lib/io/file_io.py", line 77, in _preread_check
    self._read_buf = _pywrap_file_io.BufferedInputStream(
tensorflow.python.framework.errors_impl.NotFoundError: /home/ironbong_jr/mlops/project/Group-5-Default-of-Credit-Card-Clients-IE7374/airflow/dags/schema.pbtxt; No such file or directory
[2024-03-13T00:29:35.842-0400] {taskinstance.py:1149} INFO - Marking task as UP_FOR_RETRY. dag_id=predict_data, task_id=validate_test, execution_date=20240312T000000, start_date=20240313T042935, end_date=20240313T042935
[2024-03-13T00:29:35.864-0400] {standard_task_runner.py:107} ERROR - Failed to execute job 112 for task validate_test (/home/ironbong_jr/mlops/project/Group-5-Default-of-Credit-Card-Clients-IE7374/airflow/dags/schema.pbtxt; No such file or directory; 432715)
[2024-03-13T00:29:35.898-0400] {local_task_job_runner.py:234} INFO - Task exited with return code 1
[2024-03-13T00:29:35.925-0400] {taskinstance.py:3312} INFO - 0 downstream tasks scheduled from follow-on schedule check
