[2024-03-12T18:19:01.629-0400] {taskinstance.py:1979} INFO - Dependencies all met for dep_context=non-requeueable deps ti=<TaskInstance: train_data.Train_model manual__2024-03-12T22:18:08.901670+00:00 [queued]>
[2024-03-12T18:19:01.634-0400] {taskinstance.py:1979} INFO - Dependencies all met for dep_context=requeueable deps ti=<TaskInstance: train_data.Train_model manual__2024-03-12T22:18:08.901670+00:00 [queued]>
[2024-03-12T18:19:01.634-0400] {taskinstance.py:2193} INFO - Starting attempt 1 of 3
[2024-03-12T18:19:01.655-0400] {taskinstance.py:2217} INFO - Executing <Task(PythonOperator): Train_model> on 2024-03-12 22:18:08.901670+00:00
[2024-03-12T18:19:01.663-0400] {standard_task_runner.py:60} INFO - Started process 379188 to run task
[2024-03-12T18:19:01.667-0400] {standard_task_runner.py:87} INFO - Running: ['airflow', 'tasks', 'run', 'train_data', 'Train_model', 'manual__2024-03-12T22:18:08.901670+00:00', '--job-id', '68', '--raw', '--subdir', 'DAGS_FOLDER/train_dag.py', '--cfg-path', '/tmp/tmpy009bqhw']
[2024-03-12T18:19:01.667-0400] {standard_task_runner.py:88} INFO - Job 68: Subtask Train_model
[2024-03-12T18:19:01.709-0400] {task_command.py:423} INFO - Running <TaskInstance: train_data.Train_model manual__2024-03-12T22:18:08.901670+00:00 [running]> on host DESKTOP-6U7QAQN.
[2024-03-12T18:19:01.770-0400] {taskinstance.py:2513} INFO - Exporting env vars: AIRFLOW_CTX_DAG_EMAIL='youremail@email.com' AIRFLOW_CTX_DAG_OWNER='airflow' AIRFLOW_CTX_DAG_ID='train_data' AIRFLOW_CTX_TASK_ID='Train_model' AIRFLOW_CTX_EXECUTION_DATE='2024-03-12T22:18:08.901670+00:00' AIRFLOW_CTX_TRY_NUMBER='1' AIRFLOW_CTX_DAG_RUN_ID='manual__2024-03-12T22:18:08.901670+00:00'
[2024-03-12T18:19:01.900-0400] {connectionpool.py:874} WARNING - Retrying (Retry(total=4, connect=4, read=5, redirect=5, status=5)) after connection broken by 'NewConnectionError('<urllib3.connection.HTTPConnection object at 0x7f43abd0d510>: Failed to establish a new connection: [Errno 111] Connection refused')': /api/2.0/mlflow/runs/create
[2024-03-12T18:19:06.127-0400] {connectionpool.py:874} WARNING - Retrying (Retry(total=3, connect=3, read=5, redirect=5, status=5)) after connection broken by 'NewConnectionError('<urllib3.connection.HTTPConnection object at 0x7f43abd0de10>: Failed to establish a new connection: [Errno 111] Connection refused')': /api/2.0/mlflow/runs/create
[2024-03-12T18:19:14.376-0400] {connectionpool.py:874} WARNING - Retrying (Retry(total=2, connect=2, read=5, redirect=5, status=5)) after connection broken by 'NewConnectionError('<urllib3.connection.HTTPConnection object at 0x7f43abd0de70>: Failed to establish a new connection: [Errno 111] Connection refused')': /api/2.0/mlflow/runs/create
[2024-03-12T18:19:31.283-0400] {connectionpool.py:874} WARNING - Retrying (Retry(total=1, connect=1, read=5, redirect=5, status=5)) after connection broken by 'NewConnectionError('<urllib3.connection.HTTPConnection object at 0x7f43abd0ef50>: Failed to establish a new connection: [Errno 111] Connection refused')': /api/2.0/mlflow/runs/create
[2024-03-12T18:20:03.369-0400] {connectionpool.py:874} WARNING - Retrying (Retry(total=0, connect=0, read=5, redirect=5, status=5)) after connection broken by 'NewConnectionError('<urllib3.connection.HTTPConnection object at 0x7f43abd0ebf0>: Failed to establish a new connection: [Errno 111] Connection refused')': /api/2.0/mlflow/runs/create
[2024-03-12T18:20:03.370-0400] {taskinstance.py:2731} ERROR - Task failed with exception
Traceback (most recent call last):
  File "/home/ironbong_jr/mlops/project/project/lib/python3.10/site-packages/urllib3/connection.py", line 198, in _new_conn
    sock = connection.create_connection(
  File "/home/ironbong_jr/mlops/project/project/lib/python3.10/site-packages/urllib3/util/connection.py", line 85, in create_connection
    raise err
  File "/home/ironbong_jr/mlops/project/project/lib/python3.10/site-packages/urllib3/util/connection.py", line 73, in create_connection
    sock.connect(sa)
ConnectionRefusedError: [Errno 111] Connection refused

The above exception was the direct cause of the following exception:

Traceback (most recent call last):
  File "/home/ironbong_jr/mlops/project/project/lib/python3.10/site-packages/urllib3/connectionpool.py", line 793, in urlopen
    response = self._make_request(
  File "/home/ironbong_jr/mlops/project/project/lib/python3.10/site-packages/urllib3/connectionpool.py", line 496, in _make_request
    conn.request(
  File "/home/ironbong_jr/mlops/project/project/lib/python3.10/site-packages/urllib3/connection.py", line 400, in request
    self.endheaders()
  File "/usr/lib/python3.10/http/client.py", line 1278, in endheaders
    self._send_output(message_body, encode_chunked=encode_chunked)
  File "/usr/lib/python3.10/http/client.py", line 1038, in _send_output
    self.send(msg)
  File "/usr/lib/python3.10/http/client.py", line 976, in send
    self.connect()
  File "/home/ironbong_jr/mlops/project/project/lib/python3.10/site-packages/urllib3/connection.py", line 238, in connect
    self.sock = self._new_conn()
  File "/home/ironbong_jr/mlops/project/project/lib/python3.10/site-packages/urllib3/connection.py", line 213, in _new_conn
    raise NewConnectionError(
urllib3.exceptions.NewConnectionError: <urllib3.connection.HTTPConnection object at 0x7f43abd0f460>: Failed to establish a new connection: [Errno 111] Connection refused

The above exception was the direct cause of the following exception:

Traceback (most recent call last):
  File "/home/ironbong_jr/mlops/project/project/lib/python3.10/site-packages/requests/adapters.py", line 486, in send
    resp = conn.urlopen(
  File "/home/ironbong_jr/mlops/project/project/lib/python3.10/site-packages/urllib3/connectionpool.py", line 877, in urlopen
    return self.urlopen(
  File "/home/ironbong_jr/mlops/project/project/lib/python3.10/site-packages/urllib3/connectionpool.py", line 877, in urlopen
    return self.urlopen(
  File "/home/ironbong_jr/mlops/project/project/lib/python3.10/site-packages/urllib3/connectionpool.py", line 877, in urlopen
    return self.urlopen(
  [Previous line repeated 2 more times]
  File "/home/ironbong_jr/mlops/project/project/lib/python3.10/site-packages/urllib3/connectionpool.py", line 847, in urlopen
    retries = retries.increment(
  File "/home/ironbong_jr/mlops/project/project/lib/python3.10/site-packages/urllib3/util/retry.py", line 515, in increment
    raise MaxRetryError(_pool, url, reason) from reason  # type: ignore[arg-type]
urllib3.exceptions.MaxRetryError: HTTPConnectionPool(host='127.0.0.1', port=5000): Max retries exceeded with url: /api/2.0/mlflow/runs/create (Caused by NewConnectionError('<urllib3.connection.HTTPConnection object at 0x7f43abd0f460>: Failed to establish a new connection: [Errno 111] Connection refused'))

During handling of the above exception, another exception occurred:

Traceback (most recent call last):
  File "/home/ironbong_jr/mlops/project/project/lib/python3.10/site-packages/mlflow/utils/rest_utils.py", line 108, in http_request
    return _get_http_response_with_retries(
  File "/home/ironbong_jr/mlops/project/project/lib/python3.10/site-packages/mlflow/utils/request_utils.py", line 212, in _get_http_response_with_retries
    return session.request(method, url, allow_redirects=allow_redirects, **kwargs)
  File "/home/ironbong_jr/mlops/project/project/lib/python3.10/site-packages/requests/sessions.py", line 589, in request
    resp = self.send(prep, **send_kwargs)
  File "/home/ironbong_jr/mlops/project/project/lib/python3.10/site-packages/requests/sessions.py", line 703, in send
    r = adapter.send(request, **kwargs)
  File "/home/ironbong_jr/mlops/project/project/lib/python3.10/site-packages/requests/adapters.py", line 519, in send
    raise ConnectionError(e, request=request)
requests.exceptions.ConnectionError: HTTPConnectionPool(host='127.0.0.1', port=5000): Max retries exceeded with url: /api/2.0/mlflow/runs/create (Caused by NewConnectionError('<urllib3.connection.HTTPConnection object at 0x7f43abd0f460>: Failed to establish a new connection: [Errno 111] Connection refused'))

During handling of the above exception, another exception occurred:

Traceback (most recent call last):
  File "/home/ironbong_jr/mlops/project/project/lib/python3.10/site-packages/airflow/models/taskinstance.py", line 444, in _execute_task
    result = _execute_callable(context=context, **execute_callable_kwargs)
  File "/home/ironbong_jr/mlops/project/project/lib/python3.10/site-packages/airflow/models/taskinstance.py", line 414, in _execute_callable
    return execute_callable(context=context, **execute_callable_kwargs)
  File "/home/ironbong_jr/mlops/project/project/lib/python3.10/site-packages/airflow/operators/python.py", line 200, in execute
    return_value = self.execute_callable()
  File "/home/ironbong_jr/mlops/project/project/lib/python3.10/site-packages/airflow/operators/python.py", line 217, in execute_callable
    return self.python_callable(*self.op_args, **self.op_kwargs)
  File "/home/ironbong_jr/mlops/project/Group-5-Default-of-Credit-Card-Clients-IE7374/airflow/dags/ml/train_model.py", line 62, in train_model
    with mlflow.start_run():
  File "/home/ironbong_jr/mlops/project/project/lib/python3.10/site-packages/mlflow/tracking/fluent.py", line 381, in start_run
    active_run_obj = client.create_run(
  File "/home/ironbong_jr/mlops/project/project/lib/python3.10/site-packages/mlflow/tracking/client.py", line 353, in create_run
    return self._tracking_client.create_run(experiment_id, start_time, tags, run_name)
  File "/home/ironbong_jr/mlops/project/project/lib/python3.10/site-packages/mlflow/tracking/_tracking_service/client.py", line 139, in create_run
    return self.store.create_run(
  File "/home/ironbong_jr/mlops/project/project/lib/python3.10/site-packages/mlflow/store/tracking/rest_store.py", line 187, in create_run
    response_proto = self._call_endpoint(CreateRun, req_body)
  File "/home/ironbong_jr/mlops/project/project/lib/python3.10/site-packages/mlflow/store/tracking/rest_store.py", line 60, in _call_endpoint
    return call_endpoint(self.get_host_creds(), endpoint, method, json_body, response_proto)
  File "/home/ironbong_jr/mlops/project/project/lib/python3.10/site-packages/mlflow/utils/rest_utils.py", line 219, in call_endpoint
    response = http_request(**call_kwargs)
  File "/home/ironbong_jr/mlops/project/project/lib/python3.10/site-packages/mlflow/utils/rest_utils.py", line 130, in http_request
    raise MlflowException(f"API request to {url} failed with exception {e}")
mlflow.exceptions.MlflowException: API request to http://127.0.0.1:5000/api/2.0/mlflow/runs/create failed with exception HTTPConnectionPool(host='127.0.0.1', port=5000): Max retries exceeded with url: /api/2.0/mlflow/runs/create (Caused by NewConnectionError('<urllib3.connection.HTTPConnection object at 0x7f43abd0f460>: Failed to establish a new connection: [Errno 111] Connection refused'))
[2024-03-12T18:20:03.389-0400] {taskinstance.py:1149} INFO - Marking task as UP_FOR_RETRY. dag_id=train_data, task_id=Train_model, execution_date=20240312T221808, start_date=20240312T221901, end_date=20240312T222003
[2024-03-12T18:20:03.405-0400] {standard_task_runner.py:107} ERROR - Failed to execute job 68 for task Train_model (API request to http://127.0.0.1:5000/api/2.0/mlflow/runs/create failed with exception HTTPConnectionPool(host='127.0.0.1', port=5000): Max retries exceeded with url: /api/2.0/mlflow/runs/create (Caused by NewConnectionError('<urllib3.connection.HTTPConnection object at 0x7f43abd0f460>: Failed to establish a new connection: [Errno 111] Connection refused')); 379188)
[2024-03-12T18:20:03.414-0400] {local_task_job_runner.py:234} INFO - Task exited with return code 1
[2024-03-12T18:20:03.421-0400] {taskinstance.py:3312} INFO - 0 downstream tasks scheduled from follow-on schedule check
