[2024-03-12T17:43:35.081-0400] {taskinstance.py:1979} INFO - Dependencies all met for dep_context=non-requeueable deps ti=<TaskInstance: train_data.pre_process manual__2024-03-12T21:43:07.149428+00:00 [queued]>
[2024-03-12T17:43:35.085-0400] {taskinstance.py:1979} INFO - Dependencies all met for dep_context=requeueable deps ti=<TaskInstance: train_data.pre_process manual__2024-03-12T21:43:07.149428+00:00 [queued]>
[2024-03-12T17:43:35.085-0400] {taskinstance.py:2193} INFO - Starting attempt 1 of 3
[2024-03-12T17:43:35.105-0400] {taskinstance.py:2217} INFO - Executing <Task(PythonOperator): pre_process> on 2024-03-12 21:43:07.149428+00:00
[2024-03-12T17:43:35.111-0400] {standard_task_runner.py:60} INFO - Started process 369578 to run task
[2024-03-12T17:43:35.115-0400] {standard_task_runner.py:87} INFO - Running: ['airflow', 'tasks', 'run', 'train_data', 'pre_process', 'manual__2024-03-12T21:43:07.149428+00:00', '--job-id', '51', '--raw', '--subdir', 'DAGS_FOLDER/train_dag.py', '--cfg-path', '/tmp/tmp6iqw9l8k']
[2024-03-12T17:43:35.116-0400] {standard_task_runner.py:88} INFO - Job 51: Subtask pre_process
[2024-03-12T17:43:35.145-0400] {task_command.py:423} INFO - Running <TaskInstance: train_data.pre_process manual__2024-03-12T21:43:07.149428+00:00 [running]> on host DESKTOP-6U7QAQN.
[2024-03-12T17:43:35.202-0400] {taskinstance.py:2513} INFO - Exporting env vars: AIRFLOW_CTX_DAG_EMAIL='youremail@email.com' AIRFLOW_CTX_DAG_OWNER='airflow' AIRFLOW_CTX_DAG_ID='train_data' AIRFLOW_CTX_TASK_ID='pre_process' AIRFLOW_CTX_EXECUTION_DATE='2024-03-12T21:43:07.149428+00:00' AIRFLOW_CTX_TRY_NUMBER='1' AIRFLOW_CTX_DAG_RUN_ID='manual__2024-03-12T21:43:07.149428+00:00'
[2024-03-12T17:43:38.173-0400] {taskinstance.py:2731} ERROR - Task failed with exception
Traceback (most recent call last):
  File "/home/ironbong_jr/mlops/project/project/lib/python3.10/site-packages/airflow/models/taskinstance.py", line 444, in _execute_task
    result = _execute_callable(context=context, **execute_callable_kwargs)
  File "/home/ironbong_jr/mlops/project/project/lib/python3.10/site-packages/airflow/models/taskinstance.py", line 414, in _execute_callable
    return execute_callable(context=context, **execute_callable_kwargs)
  File "/home/ironbong_jr/mlops/project/project/lib/python3.10/site-packages/airflow/operators/python.py", line 200, in execute
    return_value = self.execute_callable()
  File "/home/ironbong_jr/mlops/project/project/lib/python3.10/site-packages/airflow/operators/python.py", line 217, in execute_callable
    return self.python_callable(*self.op_args, **self.op_kwargs)
  File "/home/ironbong_jr/mlops/project/Group-5-Default-of-Credit-Card-Clients-IE7374/airflow/dags/preprocess_data/preprocess.py", line 16, in process
    with open(trainpath, 'wb') as file:
FileNotFoundError: [Errno 2] No such file or directory: '/home/ironbong_jr/mlops/project/Group-5-Default-of-Credit-Card-Clients-IE7374/airflow/dags/dags/data/train_processed_data.pkl'
[2024-03-12T17:43:38.178-0400] {taskinstance.py:1149} INFO - Marking task as UP_FOR_RETRY. dag_id=train_data, task_id=pre_process, execution_date=20240312T214307, start_date=20240312T214335, end_date=20240312T214338
[2024-03-12T17:43:38.201-0400] {standard_task_runner.py:107} ERROR - Failed to execute job 51 for task pre_process ([Errno 2] No such file or directory: '/home/ironbong_jr/mlops/project/Group-5-Default-of-Credit-Card-Clients-IE7374/airflow/dags/dags/data/train_processed_data.pkl'; 369578)
[2024-03-12T17:43:38.226-0400] {local_task_job_runner.py:234} INFO - Task exited with return code 1
[2024-03-12T17:43:38.236-0400] {taskinstance.py:3312} INFO - 0 downstream tasks scheduled from follow-on schedule check
